Workbook

Sheet Dashboard
A1: Indicador | B1: Valor
A2: Total de Vendas | B2: =SUM(Vendas!F:F) -> 18234.459
A3: Total de Despesas | B3: =SUM(Despesas!D:D) -> 23739.78
A4: Lucro Líquido | B4: =B2-B3+G9+D14+Dashboard!B37+Dashboard!H22 -> -5505.3209 | D4: 1829.52 | E4: ESTOQUE
D5: =B4+D4 -> -3675.8009

Sheet Vendas
A1: Data | B1: Cliente | C1: Produto | D1: Quantidade | E1: Valor Unitário | F1: Valor Venda | G1: Forma Pagamento | H1: Taxa | I1: Valor Líquido | J1: Status Entrega
A2: 46162 | C2: CAMARÃO INTEIRO 51/60 | D2: 1 | E2: 34.9 | F2: =D2*E2 -> 34.9 | G2: DINHEIRO | I2: =F2-H2 -> 34.9 | J2: OK
A3: 46163 | C3: CAMARÃO INTEIRO 51/60 | D3: 1 | E3: 34.9 | F3: =D3*E3 -> 34.9 | G3: PIX | I3: =F3-H3 -> 34.9 | J3: OK
A4: 46164 | C4: CAMARÃO INTEIRO 51/60 | D4: 1 | E4: 29.9 | F4: =D4*E4 -> 29.9 | G4: PIX | I4: =F4-H4 -> 29.9 | J4: OK REVENDA
A5: 46165 | C5: CAMARÃO INTEIRO 51/60 | D5: 1 | E5: 33.95 | F5: =D5*E5 -> 33.95 | G5: CREDITO | I5: =F5-H5 -> 33.95 | J5: OK
A6: 46166 | C6: FILE DE CAMARÃO G | D6: 1 | E6: 60.9 | F6: =D6*E6 -> 60.9 | G6: PIX | I6: =F6-H6 -> 60.9 | J6: OK REVENDA
A7: 46167 | C7: FILE DE TILAPIA | D7: 1.1 | E7: 50.1 | F7: =D7*E7 -> 55.11 | G7: CREDITO | I7: =F7-H7 -> 55.11 | J7: OK
A8: 46168 | C8: FILE DE CAMARÃO G | D8: 1 | E8: 74.9 | F8: =D8*E8 -> 74.9 | I8: =F8-H8 -> 74.9 | J8: OK
A9: 46169 | B9: CLEBIA | C9: CAMARÃO INTEIRO 51/60 | D9: 1 | E9: 34.9 | F9: =D9*E9 -> 34.9 | G9: PIX | I9: =F9-H9 -> 34.9 | J9: OK
A10: 46170 | C10: FILE DE TILAPIA | D10: 1 | E10: 29 | F10: =D10*E10 -> 29 | G10: PIX | I10: =F10-H10 -> 29 | J10: OK
A11: 46171 | B11: INGRID | C11: CAMARÃO INTEIRO 51/60 | D11: 1 | E11: 34.9 | F11: =D11*E11 -> 34.9 | G11: PIX | I11: =F11-H11 -> 34.9 | J11: OK
A12: 46196 | C12: CAMARÃO INTEIRO 51/60 | D12: 1 | E12: 34.9 | F12: =D12*E12 -> 34.9 | G12: PIX | I12: =F12-H12 -> 34.9 | J12: OK
A13: 46196 | C13: CAMARÃO INTEIRO 51/60 | D13: 1 | E13: 34.9 | F13: =D13*E13 -> 34.9 | G13: PIX | I13: =F13-H13 -> 34.9 | J13: OK
A14: 46166 | C14: FILE DE TILAPIA | D14: 1 | E14: 54.9 | F14: =D14*E14 -> 54.9 | I14: =F14-H14 -> 54.9 | J14: OK
A15: 46167 | C15: FILE DE SALMÃO | D15: 2 | E15: 119.9 | F15: =D15*E15 -> 239.8 | I15: =F15-H15 -> 239.8 | J15: OK
A16: 46167 | C16: FILE DE TILAPIA | D16: 2 | E16: 46.31 | F16: =D16*E16 -> 92.62 | I16: =F16-H16 -> 92.62 | J16: OK
A17: 46169 | C17: FILE DE CAMARÃO 61/70 | D17: 1 | F17: =D17*E17 -> 0 | I17: =F17-H17 -> 0 | J17: Blogueira
A18: 46171 | B18: JOSILEIDE | C18: FILE DE TILAPIA | D18: 2 | E18: 54.9 | F18: =D18*E18 -> 109.8 | G18: PIX | I18: =F18-H18 -> 109.8 | J18: OK
A19: 46171 | C19: FILE DE TILAPIA | D19: 1 | E19: 54.9 | F19: =D19*E19 -> 54.9 | I19: =F19-H19 -> 54.9 | J19: OK
A20: 46171 | C20: CAMARÃO INTEIRO 51/60 | D20: 1 | E20: 34.9 | F20: =D20*E20 -> 34.9 | G20: PIX | I20: =F20-H20 -> 34.9 | J20: OK
A21: 46172 | C21: CAMARÃO INTEIRO 51/60 | D21: 2 | E21: 34.9 | F21: =D21*E21 -> 69.8 | I21: =F21-H21 -> 69.8 | J21: OK
A22: 46172 | C22: FILE DE TILAPIA | D22: 1 | E22: 54.9 | F22: =D22*E22 -> 54.9 | G22: PIX | I22: =F22-H22 -> 54.9 | J22: OK
A23: 46172 | B23: TASSO | C23: CAMARÃO INTEIRO 51/60 | D23: 2 | E23: 34.9 | F23: =D23*E23 -> 69.8 | G23: PIX | I23: =F23-H23 -> 69.8
A24: 46173 | C24: FILE DE TILAPIA | D24: 2 | E24: 54.9 | F24: =D24*E24 -> 109.8 | G24: PIX | I24: =F24-H24 -> 109.8
A25: 46173 | C25: CAMARÃO INTEIRO 51/60 | D25: 1 | E25: 34.9 | F25: =D25*E25 -> 34.9 | G25: DINHEIRO E PIX | I25: =F25-H25 -> 34.9
A26: 46173 | B26: CELEBRE | C26: CAMARÃO INTEIRO 51/60 | D26: 2 | E26: 34.9 | F26: =D26*E26 -> 69.8 | G26: PIX | I26: =F26-H26 -> 69.8
A27: 46173 | B27: LUANA | C27: CAMARÃO INTEIRO 51/60 | D27: 2 | E27: 34.9 | F27: =D27*E27 -> 69.8 | G27: PIX | I27: =F27-H27 -> 69.8
A28: 46174 | C28: FILE DE TILAPIA | D28: 2 | E28: 54.9 | F28: =D28*E28 -> 109.8 | I28: =F28-H28 -> 109.8
A29: 46174 | C29: FILE DE SALMÃO | D29: 2 | E29: 119.9 | F29: =D29*E29 -> 239.8 | I29: =F29-H29 -> 239.8
A30: 46178 | B30: WELLINTON | C30: FILE DE SALMÃO | D30: 1 | E30: 120 | F30: =D30*E30 -> 120 | I30: =F30-H30 -> 120
A31: 46178 | B31: WELLINTON | C31: CAMARÃO INTEIRO 51/60 | D31: 1 | E31: 29.9 | F31: =D31*E31 -> 29.9 | I31: =F31-H31 -> 29.9
A32: 46178 | C32: CAMARÃO INTEIRO 51/60 | D32: 1 | E32: 29.9 | F32: =D32*E32 -> 29.9 | G32: DINHEIRO | I32: =F32-H32 -> 29.9
A33: 46178 | B33: LIVIA | C33: FILE DE TILAPIA | D33: 2 | E33: 59.9 | F33: =D33*E33 -> 119.8 | I33: =F33-H33 -> 119.8
A34: 46178 | B34: LIVIA | C34: FILE DE SALMÃO | D34: 0.69 | E34: 119.9 | F34: =D34*E34 -> 82.731 | I34: =F34-H34 -> 82.731
A35: 46178 | B35: ELAINE | C35: FILE DE TILAPIA | D35: 2 | E35: 49.9 | F35: =D35*E35 -> 99.8 | G35: PIX | I35: =F35-H35 -> 99.8
A36: 46178 | B36: LUCIVANIA | C36: CAMARÃO INTEIRO 51/60 | D36: 1 | E36: 29.9 | F36: =D36*E36 -> 29.9 | G36: PIX | I36: =F36-H36 -> 29.9
A37: 46178 | B37: LUCIVANIA | C37: FILE DE CAMARÃO 61/70 | D37: 2 | E37: 55 | F37: =D37*E37 -> 110 | G37: PIX | I37: =F37-H37 -> 110
A38: 46178 | C38: FILE DE CAMARÃO G | D38: 1 | E38: 60 | F38: =D38*E38 -> 60 | G38: PIX | I38: =F38-H38 -> 60
A39: 46178 | C39: FILE DE TILAPIA | D39: 1 | E39: 49.9 | F39: =D39*E39 -> 49.9 | I39: =F39-H39 -> 49.9
A40: 46179 | B40: MAECELOS | C40: FILE DE CAMARÃO G | D40: 9 | F40: =D40*E40 -> 0 | I40: =F40-H40 -> 0 | J40: A PAGAR
...

Sheet Compras
A1: Data | B1: Fornecedor | C1: Produto | D1: Quantidade Comprada (KG) | E1: Custo Unitário | F1: Valor Total
A2: 46162 | B2: CJ PESCADOS | C2: CAMARÃO INTEIRO 51/60 | D2: 20 | E2: 25 | F2: =D2*E2 -> 500
A3: 46162 | B3: CJ PESCADOS | C3: FILE DE CAMARÃO 61/70 | D3: 10 | E3: 40 | F3: =D3*E3 -> 400
A4: 46162 | B4: CJ PESCADOS | C4: FILE DE CAMARÃO G | D4: 18 | E4: 45 | F4: =D4*E4 -> 810
A5: 46167 | B5: FERNANDO DO CAMARÀO | C5: FILE DE SALMÃO | D5: 2 | E5: 95 | F5: =D5*E5 -> 190
A6: 46169 | B6: KONDELLI (SÃO LUIZ) | C6: FILE DE SALMÃO | D6: 3.3 | E6: 89.9 | F6: =D6*E6 -> 296.67
A7: 46170 | B7: CHALES PESCADOS | C7: FILE DE TILAPIA | D7: 15 | E7: 35 | F7: =D7*E7 -> 525
A8: 04/06.26 | B8: CHALES PESCADOS | C8: FILE DE TILAPIA | D8: 40 | E8: 35 | F8: =D8*E8 -> 1400
A9: 46178 | B9: ALDEIR | C9: CAMARÃO INTEIRO 51/60 | D9: 45 | E9: 19 | F9: =D9*E9 -> 855
A10: 46178 | B10: FABINHO | C10: FILE DE SALMÃO | D10: 2 | E10: 87 | F10: =D10*E10 -> 174
A11: 46189 | B11: CJ PESCADOS | C11: FILE DE CAMARÃO EXTRA G 16/20 | D11: 30 | E11: 60 | F11: =D11*E11 -> 1800
A12: 46189 | B12: FERNANDO DO CAMARÀO | C12: FILE DE SALMÃO | D12: 1.7882 | E12: 85 | F12: =D12*E12 -> 151.997
A13: 46192 | B13: DILAMAR | C13: CAMARÃO INTEIRO 51/60 | D13: 10.052 | E13: 19.99 | F13: =D13*E13 -> 200.93948
A14: 46196 | B14: FERNANDO DO CAMARÀO | C14: FILE DE SALMÃO | D14: 2.7 | E14: 85 | F14: =D14*E14 -> 229.5
A15: 46196 | B15: FERNANDO DO CAMARÀO | C15: SARDINHA EVICERADA COM CABEÇA | D15: 3 | E15: 17 | F15: =D15*E15 -> 51
A16: 46199 | B16: CHALES PESCADOS | C16: FILE DE TILAPIA | D16: 10 | E16: 35 | F16: =D16*E16 -> 350
A17: 46206 | B17: DILAMAR PESCADO | C17: CAMARÃO INTEIRO 51/60 | D17: 11.5 | E17: 22.06 | F17: =D17*E17 -> 253.69
A18: 46213 | B18: DILAMAR PESCADO | C18: CAMARÃO INTEIRO 51/60 | D18: 20 | E18: 22 | F18: =D18*E18 -> 440
F19: =D19*E19 -> 0
A20: 46213 | B20: CHALES PESCADOS | C20: FILE DE TILAPIA | D20: 20 | E20: 35 | F20: =D20*E20 -> 700
A21: 46219 | B21: MUCURIPE | C21: FILE DE CAMARÃO GG | D21: 8 | E21: 55 | F21: =D21*E21 -> 440 | G21: KILO COM PELE 85,00 PERCDE 200G NA RETIRADA DA PELE
A22: 46220 | B22: CESAR | C22: FILE DE TILAPIA | D22: 13.5 | E22: 35 | F22: =D22*E22 -> 472.5
A23: 46224 | B23: SÓ PEIXES PESCADOS | C23: FILE DE SALMÃO | D23: 2.4 | E23: 90.8 | F23: =D23*E23 -> 217.92 | G23: KILO COM PELE 85,00 PERCDE 200G NA RETIRADA DA PELE
A24: 46225 | B24: WS PESCADOS | C24: POSTA DE ATUM | D24: 2 | E24: 14 | F24: =D24*E24 -> 28
A25: 46227 | B25: ARACATI PESCADOS | C25: CAMARÃO INTEIRO 51/60 | D25: 10 | E25: 22.5 | F25: =D25*E25 -> 225
A26: 46228 | B26: MUCURIPE | C26: FILE DE CAMARÃO G | D26: 5 | E26: 66 | F26: =D26*E26 -> 330 | G26: FOI COMPRADO 10G DE CAMARÃO INTEIRO E TRANSFORMADO EM 5 G DE FILE DE CAMARÃO
A27: 46228 | B27: MUCURIPE | C27: FILE DE SALMÃO | D27: 0.92 | E27: 109 | F27: =D27*E27 -> 100.28 | G27: COM PE;E COM A RETIRADA DA PELE FICOU 920G
A28: 46233 | B28: GEOVA | C28: CAMARÃO INTEIRO 51/60 | D28: 16 | E28: 23 | F28: =D28*E28 -> 368 | G28: FRESCO
A29: 46233 | B29: CHARLES | C29: FILE DE CAMARÃO GG | D29: 8 | E29: 56 | F29: =D29*E29 -> 448
A30: 46233 | B30: CHARLES | C30: FILE DE TILAPIA | D30: 30 | E30: 36.17 | F30: =D30*E30 -> 1085.1
A31: 46233 | B31: ARACATI PESCADOS | C31: CAMARÃO INTEIRO 51/60 | D31: 19 | E31: 22.11 | F31: =D31*E31 -> 420.09
A32: 46236 | C32: FILE DE CAMARÃO 61/70 | D32: 5 | E32: 60 | F32: =D32*E32 -> 300
A33: 46236 | B33: MUCURIOE | C33: FILE DE SALMÃO | D33: 1.6 | E33: 75 | F33: =D33*E33 -> 120
A34: 46236 | B34: MESSEJANA | C34: FILE DE CAMARÃO G | D34: 5 | E34: 60 | F34: =D34*E34 -> 300
A35: 46239 | C35: FILE DE CAMARÃO GG | D35: 2.1 | E35: 66.66 | F35: =D35*E35 -> 139.986
A36: 46233 | C36: CAMARÃO G SEM CABEÇA | D36: 1 | E36: 30 | F36: =D36*E36 -> 30
A37: 46240 | B37: CHARLES | C37: FILE DE TILAPIA | D37: 21.5 | E37: 34.98 | F37: =D37*E37 -> 752.07
A38: 46240 | B38: SÓ PEIXES PESCADOS | C38: FILE DE SALMÃO | D38: 2.4 | E38: 68.25 | F38: =D38*E38 -> 163.8
A39: 46240 | B39: ARACATI PESCADOS | C39: CAMARÃO INTEIRO 51/60 | D39: 5 | E39: 24 | F39: =D39*E39 -> 120
B40: ARACATI PESCADOS | C40: FILE DE CAMARÃO 61/70 | D40: 3 | E40: 55 | F40: =D40*E40 -> 165
...

Sheet Estoque
A1: Produto | B1: Estoque Inicial | C1: Entradas (Compras) | D1: Saídas (Vendas) | E1: Estoque Atual | F1: DIFERENÇA ESTOQUE E CONTAGEM | G1: COMO FUNCIONA
A2: CAMARÃO INTEIRO 51/60 | C2: =SUMIF(Compras!C:C,A2,Compras!D:D) -> 156.552 | D2: =SUMIF(Vendas!C:C,A2,Vendas!D:D) -> 167.5 | E2: =B2+C2-D2 -> -10.948 | G2: Ao lançar uma compra na aba Compras, o estoque aumenta.
A3: FILE DE CAMARÃO 61/70 | C3: =SUMIF(Compras!C:C,A3,Compras!D:D) -> 18 | D3: =SUMIF(Vendas!C:C,A3,Vendas!D:D) -> 13.5 | E3: =B3+C3-D3 -> 4.5 | G3: Ao lançar uma venda na aba Vendas, o estoque diminui automaticamente.
A4: FILE DE CAMARÃO G | C4: =SUMIF(Compras!C:C,A4,Compras!D:D) -> 10 | D4: =SUMIF(Vendas!C:C,A4,Vendas!D:D) -> 9 | E4: =B4+C4-D4 -> 1
A5: FILE DE TILAPIA | C5: =SUMIF(Compras!C:C,A5,Compras!D:D) -> 150 | D5: =SUMIF(Vendas!C:C,A5,Vendas!D:D) -> 126.469 | E5: =B5+C5-D5 -> 23.531
A6: FILE DE SALMÃO | C6: =SUMIF(Compras!C:C,A6,Compras!D:D) -> 27.0282 | D6: =SUMIF(Vendas!C:C,A6,Vendas!D:D) -> 20.49 | E6: =B6+C6-D6 -> 6.5382
A7: FILE DE CAMARÃO EXTRA G 16/20 | C7: =SUMIF(Compras!C:C,A7,Compras!D:D) -> 30 | D7: =SUMIF(Vendas!C:C,A7,Vendas!D:D) -> 38 | E7: =B7+C7-D7 -> -8
A8: SARDINHA EVICERADA COM CABEÇA | C8: =SUMIF(Compras!C:C,A8,Compras!D:D) -> 3 | D8: =SUMIF(Vendas!C:C,A8,Vendas!D:D) -> 2.1 | E8: =B8+C8-D8 -> 0.9 | G8: CONTAGEM DO ESTOQUE DIA 13/07/26
A9: FILE DE CAMARÃO GG | C9: =SUMIF(Compras!C:C,A9,Compras!D:D) -> 28.1 | D9: =SUMIF(Vendas!C:C,A9,Vendas!D:D) -> 10 | E9: =B9+C9-D9 -> 18.1 | G9: Filé médio 61/70 | J9: 60 | K9: 1 | L9: =J9*K9 -> 60
A10: POSTA DE ATUM | C10: =SUMIF(Compras!C:C,A10,Compras!D:D) -> 6.4 | D10: =SUMIF(Vendas!C:C,A10,Vendas!D:D) -> 3 | E10: =B10+C10-D10 -> 3.4 | G10: Filé de camarão EXTRA 1620 | J10: 79.9 | K10: 0 | L10: =J10*K10 -> 0
A11: CAMARÃO G SEM CABEÇA | C11: =SUMIF(Compras!C:C,A11,Compras!D:D) -> 1 | D11: =SUMIF(Vendas!C:C,A11,Vendas!D:D) -> 0 | E11: =B11+C11-D11 -> 1 | G11: Filé tilápia- | J11: 49.9 | K11: 30 | L11: =J11*K11 -> 1497
A12: POSTA DE PARGO | C12: =SUMIF(Compras!C:C,A12,Compras!D:D) -> 2.4 | D12: =SUMIF(Vendas!C:C,A12,Vendas!D:D) -> 0 | E12: =B12+C12-D12 -> 2.4 | G12: Sardinha- | J12: 27 | K12: 1.234 | L12: =J12*K12 -> 33.318
A13: OVOS CAIPIRA | C13: =SUMIF(Compras!C:C,A13,Compras!D:D) -> 50 | D13: =SUMIF(Vendas!C:C,A13,Vendas!D:D) -> 10 | E13: =B13+C13-D13 -> 40 | G13: Camarão inteiro - | J13: 29.9 | K13: 8 | L13: =J13*K13 -> 239.2
C14: =SUMIF(Compras!C:C,A14,Compras!D:D) -> 0 | D14: =SUMIF(Vendas!C:C,A14,Vendas!D:D) -> 0 | E14: =B14+C14-D14 -> 0 | G14: Salmão | J14: 119.9 | K14: 0 | L14: =J14*K14 -> 0
C15: =SUMIF(Compras!C:C,A15,Compras!D:D) -> 0 | D15: =SUMIF(Vendas!C:C,A15,Vendas!D:D) -> 0 | E15: =B15+C15-D15 -> 0 | G15: FILE DE CAMARÃO GG | L15: =SUM(L9:L14) -> 1829.518
C16: =SUMIF(Compras!C:C,A16,Compras!D:D) -> 0 | D16: =SUMIF(Vendas!C:C,A16,Vendas!D:D) -> 0 | E16: =B16+C16-D16 -> 0 | G16: FILE DE CAMARÃO G
C17: =SUMIF(Compras!C:C,A17,Compras!D:D) -> 0 | D17: =SUMIF(Vendas!C:C,A17,Vendas!D:D) -> 0 | E17: =B17+C17-D17 -> 0 | G17: POSTA DE PARGO
C18: =SUMIF(Compras!C:C,A18,Compras!D:D) -> 0 | D18: =SUMIF(Vendas!C:C,A18,Vendas!D:D) -> 0 | E18: =B18+C18-D18 -> 0 | G18: POSTA DE ATUM
C19: =SUMIF(Compras!C:C,A19,Compras!D:D) -> 0 | D19: =SUMIF(Vendas!C:C,A19,Vendas!D:D) -> 0 | E19: =B19+C19-D19 -> 0
C20: =SUMIF(Compras!C:C,A20,Compras!D:D) -> 0 | D20: =SUMIF(Vendas!C:C,A20,Vendas!D:D) -> 0 | E20: =B20+C20-D20 -> 0
C21: =SUMIF(Compras!C:C,A21,Compras!D:D) -> 0 | D21: =SUMIF(Vendas!C:C,A21,Vendas!D:D) -> 0 | E21: =B21+C21-D21 -> 0
D22: =SUMIF(Vendas!C:C,A22,Vendas!D:D) -> 0 | E22: =B22+C22-D22 -> 0

Sheet Despesas
A1: Data | B1: Categoria | C1: Descrição | D1: Valor | E1: Forma Pagamento
A2: 46142 | B2: EQUIPAMENTO | C2: FREEZER | D2: 4014 | E2: CARTAO EM 6 X 669,00 | F2: ROBERIO
B3: EQUIPAMENTO | C3: BALANÇA | D3: 25 | F3: ARRUDA
A4: 46170 | B4: EQUIPAMENTO | C4: SELADORA | D4: 200
B5: UTENSILIOS | C5: PENEIRA, BOOL E GRAPEADOR | D5: 52
A6: 46170 | B6: EMBALAGENS | C6: SACOS | D6: 42.48
B7: EMBALAGENS | C7: SACOLAS
A8: 46172 | B8: MAT. GRAFICOS | C8: PLANFLETOS | D8: 156
B9: MAT. GRAFICOS | C9: ADESIVOS | D9: 34.9
B10: UTENSILIOS | C10: TABUA, FACA | D10: 40.35 | F10: ROBERIO
B11: UTENSILIOS | C11: MESA | D11: 289
B12: MAT. ELETRICO | C12: PROT. ELETRICO | D12: 54
B13: DESP. FIXAS | C13: ENERGIA | D13: 125 | F13: ARRUDA
A14: 28 E 30 | B14: DESP. VARIAVEL | C14: COMBUSTIVEL | D14: 40
A15: 46162 | B15: PRODUTOS | C15: CAMARÃO E FILE | D15: 1710
A16: 46167 | B16: PRODUTOS | C16: FILÉ DE SALMÃO | D16: 334 | F16: ROBERIO
A17: 46169 | B17: PRODUTOS | C17: FILÉ DE SALMÃO | D17: 294.33 | F17: ARRUDA
A18: 46169 | B18: DIVULGAÇÃO | C18: CAMARÃO INTEIRO | D18: 34.9 | E18: PARA BLOGUEIRA
A19: 46170 | B19: PRODUTOS | C19: FILE DE TILAPIA | D19: 525
B20: UTENSILIOS | C20: IMA | D20: 58
B21: UTENSILIOS | C21: BEG | D21: 192.5 | E21: CARTào 2x 96,25
B22: UTENSILIOS | C22: ISOPOR | D22: 259.85
A23: 46174 | B23: DESP. VARIAVEL | C23: COMBUSTIVEL | D23: 20
A24: 46177 | B24: MAT. DESCARTAVEL | C24: LUVA PRETA (100UND) | D24: 32.99
A25: 46177 | B25: MAT. DE LIMPEZA | C25: DETERGENTE E MULTIUSO | D25: 15
A26: 46179 | B26: ENTREGA | C26: UBER FLEX | D26: 17.3
A27: 46181 | B27: DESP. VARIAVEL | C27: COMBUSTIVEL | D27: 40
A28: 46179 | B28: EMBALAGEM | C28: UBER FLEX | D28: 15.5 | E28: PEGA OS IMAS NA GRAFICA
A29: 04/06.26 | B29: PRODUTOS | C29: FILE DE TILAPIA | D29: 1400
A30: 46178 | B30: PRODUTOS | C30: CAMARÃO INTEIRO 51/60 | D30: 855
A31: 46178 | B31: PRODUTOS | C31: FILE DE SALMÃO | D31: 174
A32: 46189 | B32: PRODUTOS | C32: FILE DE CAMARÃO EXTRA G 16/20 | D32: 1800
A33: 46189 | B33: PRODUTOS | C33: FILE DE SALMÃO | D33: 152
A34: 46190 | B34: DESP. VARIAVEL | C34: COMBUSTIVEL | D34: 20
A35: 16/06'26 | B35: EMBALAGENS | C35: SACO ( 1,274 KG) | D35: 44.59
A36: 46189 | B36: MAT. DESCARTAVEL | C36: PAPEL TOALHA | D36: 4.99
A37: 46189 | B37: MAT, ESCRITORIO | C37: CANETA MARCADOR | D37: 7.4
A38: 46190 | B38: MAT. DIVULGACÃO | C38: ETIQUETAS PRODUTOS E DA ADESIVO BAG | D38: 56
A39: 46193 | B39: MAT, ESCRITORIO | C39: MAQUINA DE PASSAR CARTÃO | D39: 86.4
A40: 46199 | B40: PRODUTOS | C40: FILE DE TILAPIA | D40: 350 | E40: PIX
...

Sheet Fluxo_Caixa
A1: Data | B1: Descrição | C1: Entradas | D1: Saídas | E1: Saldo Diário
E2: =C2-D2 -> 0
E3: =E2+C3-D3 -> 0

Sheet Clientes
A1: Cliente | B1: Telefone | C1: Endereço | D1: Forma de pagamento | E1: Valor Devido | F1: Último Pagamento

Sheet Fornecedores
A1: Fornecedor | B1: Contato | C1: Telefone | D1: ENDEREÇO | E1: Produto Fornecido | F1: Prazo Pagamento | G1: Observações
A2: CJ PESCADOS | E2: CAMARÃO INTEIRO, FILE DE CAMARÃO
A3: FERNANDO DO CAMARÀO | E3: FILE DE SALMÃO
A4: CHALES PESCADOS | E4: FILE DE TILAPIA
A5: ALDEIR | E5: CAMARÃO INTEIRO
A6: FABINHO | E6: FILE DE SALMÃO
A7: DILAMAR PESCADOS | B7: KARINE | C7: 8530674800 | D7: RUA FISCAL PERDIGÃO, 690 - CIDADE DOS FUNCIONÁRIO | E7: CAMARÃO INTEIRO FRECO | F7: PIX
A8: MESSEPLAST | B8: SUPER | C8: 85 3274.1286 | D8: RUA PROF. JOSE HENRIQUE , 27 MESSEJANA | E8: SACOS | F8: PIX
A9: AGS IMPRESSO DIGITAL LTDA | D9: 22.292.121/0001-97 | E9: ADESIVOS | F9: PIX
A10: ARACATI PEIXES E MARISCOS | C10: 85 98535.3066 | D10: RUA CORONEL GUILHERME ALENCAR, 81 - 44.729.452/0001-84 | E10: CAMARÃO INTEIRO | F10: PIX/DINHEIRO
A11: DCVR COMERCIO DE ALIMENTOS | C11: 81 815187870 | D11: RUA JOSÉ MOGICA, 10 ESCADA COM GRADEADO - PAUPINA | E11: FILE DE SALMÃO | F11: CARTÃO
A12: HENDERSON D. CAVALCANTE LTDA (CASA SUSHI)

Sheet Contas_Pagar
A1: Vencimento | B1: Fornecedor | C1: Descrição | D1: Valor | E1: Status | F1: Data Pagamento
A2: 46224 | B2: ENEL | C2: ENERGIA | D2: 130 | E2: PG

Sheet Contas_Receber
A1: Cliente | B1: Descrição | C1: Valor | D1: Vencimento | E1: Status | F1: Data Recebimento

Sheet Entregas
A1: Data | B1: Pedido | C1: Bairro | D1: Entregador | E1: Taxa Entrega | F1: Custo Combustível | G1: Lucro Entrega
G2: =E2-F2 -> 0

Sheet INVESTIMENTO
A1: INVESTIMENTO
B2: DATA | C2: VALOR | D2: FORMA
A3: ROBÉRIO | B3: 46142 | C3: 4014 | D3: CARTAO PARCELADO | E3: FREEZER
B4: 46162 | C4: 710 | D4: PIX | E4: CAMARÃO
B5: 46169 | C5: 296.67 | E5: SALMÃO
B6: 46228 | C6: 800 | E6: CAMARÃO E PEIXE
B7: 46234 | C7: 100 | E7: CAMARÃO E PEIXE
C8: 29.9 | E8: TAPETE
C9: 45 | E9: LUMINARIAS
C10: 35 | E10: OVOS CAIPIRA
C11: 22 | E11: SOQUETES
C12: =C3+C4+C5+C6+C7+C8+C9 -> 5995.57

Sheet Sheet2
